Workbook

Sheet Model structure
B2: Model setup | J2: Information on media constituents and cells | Q2: Equations
B3: Assumptions: | C3: 1. Test chemicals partition between test medium and cells
C4: 2. Test medium and cells are composed of water, proteins, and lipids
K6: Media | L6: protein content (mL/L) | M6: lipid content (mL/L)
K7: OptiMEM | L7: 0 | M7: 0
K8: DMEM Glutamax | L8: 0 | M8: 0
K9: Phenol-Red free DMEM | L9: 0 | M9: 0
K10: FBS | L10: 24 | M10: 1.9
K11: cs-FBS | L11: 46.77 | M11: 1.6
K12: d-FBS | L12: 37.69 | M12: 1.46
K14: Cells | L14: Water content (mL/106 cells) | M14: protein content (mL/106 cells) | N14: lipid content (mL/106 cells)
K15: HEK293T | L15: =M15/0.029*(0.018) -> 4.619906e-05 | M15: 7.4431818e-05 | N15: =M15/0.029*(0.953) -> 0.0024459835 | O15: =SUM(L15:N15) -> 0.0025666144
K16: HEK293H | L16: 0.00254848 | M16: 0.00022915 | N16: 9.667e-05
J17: Fish Rtgut | K17: HepG2 | L17: 0.00089 | M17: 6e-05 | N17: 5e-05
K18: HCT116 | L18: 0.00224571 | M18: 0.00030027 | N18: 6.623e-05
K19: Me-180 | L19: 0.00327303 | M19: 0.0003989 | N19: 0.00010728

Sheet User input and model output
I2: Model output
I5: 1. System information
I6: Total Test system | J6: Volumes (µL) | K6: MB (%) | L6: Information and comments
I7: System volume | J7: =SUM(J13,J19) -> 150.02 | K7: =J7/J7 -> 1 | L7: cells & media, MB = Mass Balance
B8: User input | I8: Total water volume | J8: =SUM(J14,J20) -> 149.2408 | K8: =J8/J7 -> 0.99480603 | L8: MB = Mass Balance
I9: Total protein volume | J9: =SUM(J15,J21) -> 0.7212 | K9: =J9/J7 -> 0.004807359 | L9: MB = Mass Balance
I10: Total lipid volume | J10: =SUM(J16,J22) -> 0.058 | K10: =J10/J7 -> 0.00038661512 | L10: MB = Mass Balance
B11: 1. Test system parameters
I12: Test medium | J12: Volumes (µL) | K12: MB (%) | L12: Information and comments
B13: Characteristics of Test medium | D13: Information and comments | I13: Total volume | J13: =SUM(J14:J16) -> 150 | K13: =J13/J13 -> 1 | L13: equals C14, MB = Mass Balance
B14: Medium volume (µL) | C14: 150 | D14: cells excluded | I14: Water volume | J14: =C14-SUM(J15:J16) -> 149.223 | K14: =J14/J13 -> 0.99482 | L14: mass balance, MB = Mass Balance
B15: Type of base medium | C15: OptiMEM | D15: Choose from comment (mouseover) or leave empty of not available | I15: Protein volume | J15: =C14/1000*IF(AND(C15="OptiMEM",C17="FBS"),C16*'Model structure'!L7+'User input and model output'!C18*'Model structure'!L10,IF(AND(C15="OptiMEM",C17="d-FBS"),C16*'Model structure'!L7+'User input and model output'!C18*'Model structure'!L12,IF(AND(C15="OptiMEM",C17="cs-FBS"),C16*'Model structure'!L7+'User input and model output'!C18*'Model structure'!L11,IF(AND(C15="DMEM Glutamax",C17="FBS"),C16*'Model structure'!L8+'User input and model output'!C18*'Model structure'!L10,IF(AND(C15="DMEM Glutamax",C17="d-FBS"),C16*'Model structure'!L8+'User input and model output'!C18*'Model structure'!L12,IF(AND(C15="DMEM Glutamax",C17="cs-FBS"),C16*'Model structure'!L8+'User input and model output'!C18*'Model structure'!L11,IF(AND(C15="Phenol-Red free DMEM",C17="FBS"),C16*'Model structure'!L9+'User input and model output'!C18*'Model structure'!L10,IF(AND(C15="Phenol-Red free DMEM",C17="d-FBS"),C16*'Model structure'!L9+'User input and model output'!C18*'Model structure'!L12,IF(AND(C15="Phenol-Red free DMEM",C17="cs-FBS"),C16*'Model structure'!L9+'User input and model output'!C18*'Model structure'!L11,C16*AVERAGE('Model structure'!L7:L9)+'User input and model output'!C18*AVERAGE('Model structure'!L10:L12)))))))))) -> 0.72 | K15: =J15/J13 -> 0.0048 | L15: MB = Mass Balance
B16: Fraction of base medium (%) | C16: 0.8 | D16: Percentage of medium base in the test medium | I16: Lipid volume | J16: =C14/1000*IF(AND(C15="OptiMEM",C17="FBS"),C16*'Model structure'!M7+'User input and model output'!C18*'Model structure'!M10,IF(AND(C15="OptiMEM",C17="d-FBS"),C16*'Model structure'!M7+'User input and model output'!C18*'Model structure'!M12,IF(AND(C15="OptiMEM",C17="cs-FBS"),C16*'Model structure'!M7+'User input and model output'!C18*'Model structure'!M11,IF(AND(C15="DMEM Glutamax",C17="FBS"),C16*'Model structure'!M8+'User input and model output'!C18*'Model structure'!M10,IF(AND(C15="DMEM Glutamax",C17="d-FBS"),C16*'Model structure'!M8+'User input and model output'!C18*'Model structure'!M12,IF(AND(C15="DMEM Glutamax",C17="cs-FBS"),C16*'Model structure'!M8+'User input and model output'!C18*'Model structure'!M11,IF(AND(C15="Phenol-Red free DMEM",C17="FBS"),C16*'Model structure'!M9+'User input and model output'!C18*'Model structure'!M10,IF(AND(C15="Phenol-Red free DMEM",C17="d-FBS"),C16*'Model structure'!M9+'User input and model output'!C18*'Model structure'!M12,IF(AND(C15="Phenol-Red free DMEM",C17="cs-FBS"),C16*'Model structure'!M9+'User input and model output'!C18*'Model structure'!M11,C16*AVERAGE('Model structure'!M7:M9)+'User input and model output'!C18*AVERAGE('Model structure'!M10:M13)))))))))) -> 0.057 | K16: =J16/J13 -> 0.00038 | L16: MB = Mass Balance
B17: Type of serum | C17: FBS | D17: Choose from comment (mouseover) or leave empty if not available
B18: Fraction of serum (%) | C18: 0.2 | D18: Percentage of serum in the test medium | I18: Cells | J18: Volumes (µL) | K18: MB (%) | L18: Information and comments
I19: Total volume | J19: =SUM(J20:J22) -> 0.02 | K19: =J19/J19 -> 1 | L19: Cells are solely composed of water, proteins, and lipids
B20: Characteristics of cells | D20: Information and comments | I20: Water volume | J20: =1000*IF(C21="HEK293T",C22/1000000*'Model structure'!L15,IF(C21="HEK293H",C22/1000000*'Model structure'!L16,IF(C21="HepG2",C22/1000000*'Model structure'!L17,IF(C21="HCT116",C22/1000000*'Model structure'!L18,IF(C21="ME-180",C22/1000000*'Model structure'!L19,C22/1000000*AVERAGE('Model structure'!L15:L19)))))) -> 0.0178 | K20: =J20/J19 -> 0.89 | L20: MB = Mass Balance
B21: Cell line | C21: HepG2 | D21: Choose from comment (mouseover) or leave empty if not available | I21: Protein volume | J21: =1000*IF(C21="HEK293T",C22/1000000*'Model structure'!M15,IF(C21="HEK293H",C22/1000000*'Model structure'!M16,IF(C21="HepG2",C22/1000000*'Model structure'!M17,IF(C21="HCT116",C22/1000000*'Model structure'!M18,IF(C21="ME-180",C22/1000000*'Model structure'!M19,C22/1000000*AVERAGE('Model structure'!M15:M19)))))) -> 0.0012 | K21: =J21/J19 -> 0.06 | L21: MB = Mass Balance
B22: Cell number at test start | C22: 20000 | D22: Plated cell number - Disregard cell growth | I22: Lipid volume | J22: =1000*IF(C21="HEK293T",C22/1000000*'Model structure'!N15,IF(C21="HEK293H",C22/1000000*'Model structure'!N16,IF(C21="HepG2",C22/1000000*'Model structure'!N17,IF(C21="HCT116",C22/1000000*'Model structure'!N18,IF(C21="ME-180",C22/1000000*'Model structure'!N19,C22/1000000*AVERAGE('Model structure'!N15:N19)))))) -> 0.001 | K22: =J22/J19 -> 0.05 | L22: MB = Mass Balance
B24: 2. Chemical parameters | I24: 2. Chemical partitioning
B26: Compound | C26: CAS | D26: log DBSA/w [L/L], pH 7.4, 37 °C | E26: log Dlip/w [L/L], pH 7.4, 37 °C | F26: (E)Cnom [mol/L] | I26: log Dmedium/w [L/L], pH 7.4, 37 °C | J26: log Dcell/w [L/L], pH 7.4, 37 °C | K26: fw,medium (%) | L26: fcell (%) | M26: fmedium (%) | N26: fmem (%) | O26: (E)Cfree [mol/Lw,medium] | P26: (E)Ccell [mol/Lcell] | Q26: (E)Cmem [mol/Lmem]
R27: umold | S27: umole
B28: Caffeine | C28: 58-08-2 | D28: 0.065248 | E28: 0.082216 | F28: 1e-06 | I28: =IF(D28=0,"",LOG($K$15*10^D28+$K$16*10^E28+$K$14)) -> 0.0003721765 | J28: =IF(D28=0,"",LOG($K$21*10^D28+$K$22*10^E28+$K$20)) -> 0.0086629514 | K28: =IF(D28=0,"",1/(1+10^D28*$J$15/$J$14+10^E28*$J$16/$J$14+10^J28*$J$19/$J$14)) -> 0.99383277 | L28: =IF(D28=0,"",1/(1+10^I28/10^J28*$J$13/$J$19)) -> 0.00013588468 | M28: =IF(D28=0,"",1-L28) -> 0.99986412 | N28: =IF(D28=0,"",1/(1/10^E28*$J$20/$J$22+10^D28/10^E28*$J$21/$J$22+10^I28/10^E28*$J$13/$J$22+1)) -> 8.0481034e-06 | O28: =IF(D28=0,"",F28*K28*$J$7/$J$14) -> 9.9914083e-07 | P28: =IF(D28=0,"",O28*10^J28) -> 1.019271e-06 | Q28: =IF(D28=0,"",F28*N28*$J$7/$J$22) -> 1.2073765e-06 | R28: =F28*$C$14 -> 0.00015 | S28: =$R28*L28 -> 2.0382702e-08 | T28: =R28*K28 -> 0.00014907492 | U28: =$R28*M28 -> 0.00014997962 | V28: =K28/M28 -> 0.99396784
B29: Lamotrigine | C29: 84057-84-1 | D29: 2.31 | E29: 2.58 | F29: 1e-06 | I29: =IF(D29=0,"",LOG($K$15*10^D29+$K$16*10^E29+$K$14)) -> 0.3261978 | J29: =IF(D29=0,"",LOG($K$21*10^D29+$K$22*10^E29+$K$20)) -> 1.5071796 | K29: =IF(D29=0,"",1/(1+10^D29*$J$15/$J$14+10^E29*$J$16/$J$14+10^J29*$J$19/$J$14)) -> 0.46845639 | L29: =IF(D29=0,"",1/(1+10^I29/10^J29*$J$13/$J$19)) -> 0.0020185662 | M29: =IF(D29=0,"",1-L29) -> 0.99798143 | N29: =IF(D29=0,"",1/(1/10^E29*$J$20/$J$22+10^D29/10^E29*$J$21/$J$22+10^I29/10^E29*$J$13/$J$22+1)) -> 0.0011935302 | O29: =IF(D29=0,"",F29*K29*$J$7/$J$14) -> 4.7095841e-07 | P29: =IF(D29=0,"",O29*10^J29) -> 1.5141265e-05 | Q29: =IF(D29=0,"",F29*N29*$J$7/$J$22) -> 0.0001790534 | R29: =F29*$C$14 -> 0.00015 | S29: =$R29*L29 -> 3.0278492e-07 | T29: =R29*K29 -> 7.0268458e-05 | U29: =$R29*M29 -> 0.00014969722 | V29: =K29/M29 -> 0.46940391
B30: Diclofenac | C30: 15307-79-6 | D30: 4.4 | E30: 2.64 | F30: 1e-06 | I30: =IF(D30=0,"",LOG($K$15*10^D30+$K$16*10^E30+$K$14)) -> 2.0854021 | J30: =IF(D30=0,"",LOG($K$21*10^D30+$K$22*10^E30+$K$20)) -> 3.1846482 | K30: =IF(D30=0,"",1/(1+10^D30*$J$15/$J$14+10^E30*$J$16/$J$14+10^J30*$J$19/$J$14)) -> 0.0081585941 | L30: =IF(D30=0,"",1/(1+10^I30/10^J30*$J$13/$J$19)) -> 0.0016728528 | M30: =IF(D30=0,"",1-L30) -> 0.99832715 | N30: =IF(D30=0,"",1/(1/10^E30*$J$20/$J$22+10^D30/10^E30*$J$21/$J$22+10^I30/10^E30*$J$13/$J$22+1)) -> 2.3865996e-05 | O30: =IF(D30=0,"",F30*K30*$J$7/$J$14) -> 8.2021691e-09 | P30: =IF(D30=0,"",O30*10^J30) -> 1.2548069e-05 | Q30: =IF(D30=0,"",F30*N30*$J$7/$J$22) -> 3.5803767e-06 | R30: =F30*$C$14 -> 0.00015 | S30: =$R30*L30 -> 2.5092793e-07 | T30: =R30*K30 -> 1.2237891e-06 | U30: =$R30*M30 -> 0.00014974907 | V30: =K30/M30 -> 0.0081722651
B31: 2,4-Dichlorophenoxyacetic | C31: 94-75-7 | D31: -0.92190615 | E31: -1.7889088 | F31: 1e-06 | I31: =IF(D31=0,"",LOG($K$15*10^D31+$K$16*10^E31+$K$14)) -> -0.0020020416 | J31: =IF(D31=0,"",LOG($K$21*10^D31+$K$22*10^E31+$K$20)) -> -0.04672611 | K31: =IF(D31=0,"",1/(1+10^D31*$J$15/$J$14+10^E31*$J$16/$J$14+10^J31*$J$19/$J$14)) -> 0.99929638 | L31: =IF(D31=0,"",1/(1+10^I31/10^J31*$J$13/$J$19)) -> 0.00012027142 | M31: =IF(D31=0,"",1-L31) -> 0.99987973 | N31: =IF(D31=0,"",1/(1/10^E31*$J$20/$J$22+10^D31/10^E31*$J$21/$J$22+10^I31/10^E31*$J$13/$J$22+1)) -> 1.0888042e-07 | O31: =IF(D31=0,"",F31*K31*$J$7/$J$14) -> 1.0046336e-06 | P31: =IF(D31=0,"",O31*10^J31) -> 9.0215591e-07 | Q31: =IF(D31=0,"",F31*N31*$J$7/$J$22) -> 1.6334241e-08 | R31: =F31*$C$14 -> 0.00015 | S31: =$R31*L31 -> 1.8040713e-08 | T31: =R31*K31 -> 0.00014989446 | U31: =$R31*M31 -> 0.00014998196 | V31: =K31/M31 -> 0.99941658
B32: (S)-Naproxen | C32: 22204-53-1 | D32: 0.5474918 | E32: 0.30136158 | F32: 1e-06 | I32: =IF(D32=0,"",LOG($K$15*10^D32+$K$16*10^E32+$K$14)) -> 0.0054008425 | J32: =IF(D32=0,"",LOG($K$21*10^D32+$K$22*10^E32+$K$20)) -> 0.07980996 | K32: =IF(D32=0,"",1/(1+10^D32*$J$15/$J$14+10^E32*$J$16/$J$14+10^J32*$J$19/$J$14)) -> 0.98236966 | L32: =IF(D32=0,"",1/(1+10^I32/10^J32*$J$13/$J$19)) -> 0.00015822647 | M32: =IF(D32=0,"",1-L32) -> 0.99984177 | N32: =IF(D32=0,"",1/(1/10^E32*$J$20/$J$22+10^D32/10^E32*$J$21/$J$22+10^I32/10^E32*$J$13/$J$22+1)) -> 1.3176521e-05 | O32: =IF(D32=0,"",F32*K32*$J$7/$J$14) -> 9.876165e-07 | P32: =IF(D32=0,"",O32*10^J32) -> 1.1868567e-06 | Q32: =IF(D32=0,"",F32*N32*$J$7/$J$22) -> 1.9767417e-06 | R32: =F32*$C$14 -> 0.00015 | S32: =$R32*L32 -> 2.373397e-08 | T32: =R32*K32 -> 0.00014735545 | U32: =$R32*M32 -> 0.00014997627 | V32: =K32/M32 -> 0.98252513
B33: Ibuprofen | C33: 15687-27-1 | D33: 1.6452318 | E33: 1.8629354 | F33: 1e-06 | I33: =IF(D33=0,"",LOG($K$15*10^D33+$K$16*10^E33+$K$14)) -> 0.091527064 | J33: =IF(D33=0,"",LOG($K$21*10^D33+$K$22*10^E33+$K$20)) -> 0.85658284 | K33: =IF(D33=0,"",1/(1+10^D33*$J$15/$J$14+10^E33*$J$16/$J$14+10^J33*$J$19/$J$14)) -> 0.80515679 | L33: =IF(D33=0,"",1/(1+10^I33/10^J33*$J$13/$J$19)) -> 0.00077563524 | M33: =IF(D33=0,"",1-L33) -> 0.99922436 | N33: =IF(D33=0,"",1/(1/10^E33*$J$20/$J$22+10^D33/10^E33*$J$21/$J$22+10^I33/10^E33*$J$13/$J$22+1)) -> 0.00039353205 | O33: =IF(D33=0,"",F33*K33*$J$7/$J$14) -> 8.0945713e-07 | P33: =IF(D33=0,"",O33*10^J33) -> 5.8180399e-06 | Q33: =IF(D33=0,"",F33*N33*$J$7/$J$22) -> 5.9037678e-05 | R33: =F33*$C$14 -> 0.00015 | S33: =$R33*L33 -> 1.1634529e-07 | T33: =R33*K33 -> 0.00012077352 | U33: =$R33*M33 -> 0.00014988365 | V33: =K33/M33 -> 0.80578178
B34: Torasemide | C34: 56211-40-6 | D34: 0.39857727 | E34: 0.08952541 | F34: 1e-06 | I34: =IF(D34=0,"",LOG($K$15*10^D34+$K$16*10^E34+$K$14)) -> 0.0031608227 | J34: =IF(D34=0,"",LOG($K$21*10^D34+$K$22*10^E34+$K$20)) -> 0.04205015 | K34: =IF(D34=0,"",1/(1+10^D34*$J$15/$J$14+10^E34*$J$16/$J$14+10^J34*$J$19/$J$14)) -> 0.98746193 | L34: =IF(D34=0,"",1/(1+10^I34/10^J34*$J$13/$J$19)) -> 0.00014580242 | M34: =IF(D34=0,"",1-L34) -> 0.9998542 | N34: =IF(D34=0,"",1/(1/10^E34*$J$20/$J$22+10^D34/10^E34*$J$21/$J$22+10^I34/10^E34*$J$13/$J$22+1)) -> 8.1322365e-06 | O34: =IF(D34=0,"",F34*K34*$J$7/$J$14) -> 9.9273596e-07 | P34: =IF(D34=0,"",O34*10^J34) -> 1.093664e-06 | Q34: =IF(D34=0,"",F34*N34*$J$7/$J$22) -> 1.2199981e-06 | R34: =F34*$C$14 -> 0.00015 | S34: =$R34*L34 -> 2.1870363e-08 | T34: =R34*K34 -> 0.00014811929 | U34: =$R34*M34 -> 0.00014997813 | V34: =K34/M34 -> 0.98760592
B35: Warfarin | C35: 81-81-2 | D35: 0.27761206 | E35: -0.082551864 | F35: 1e-06 | I35: =IF(D35=0,"",LOG($K$15*10^D35+$K$16*10^E35+$K$14)) -> 0.0018333114 | J35: =IF(D35=0,"",LOG($K$21*10^D35+$K$22*10^E35+$K$20)) -> 0.019135109 | K35: =IF(D35=0,"",1/(1+10^D35*$J$15/$J$14+10^E35*$J$16/$J$14+10^J35*$J$19/$J$14)) -> 0.99049193 | L35: =IF(D35=0,"",1/(1+10^I35/10^J35*$J$13/$J$19)) -> 0.00013873316 | M35: =IF(D35=0,"",1-L35) -> 0.99986127 | N35: =IF(D35=0,"",1/(1/10^E35*$J$20/$J$22+10^D35/10^E35*$J$21/$J$22+10^I35/10^E35*$J$13/$J$22+1)) -> 5.4886218e-06 | O35: =IF(D35=0,"",F35*K35*$J$7/$J$14) -> 9.9578215e-07 | P35: =IF(D35=0,"",O35*10^J35) -> 1.0406374e-06 | Q35: =IF(D35=0,"",F35*N35*$J$7/$J$22) -> 8.2340305e-07 | R35: =F35*$C$14 -> 0.00015 | S35: =$R35*L35 -> 2.0809974e-08 | T35: =R35*K35 -> 0.00014857379 | U35: =$R35*M35 -> 0.00014997919 | V35: =K35/M35 -> 0.99062936
B36: di-n-butylphthalate | C36: 84-74-2 | D36: 3.440928 | E36: 4.116066 | F36: 1e-06 | I36: =IF(D36=0,"",LOG($K$15*10^D36+$K$16*10^E36+$K$14)) -> 1.2834731 | J36: =IF(D36=0,"",LOG($K$21*10^D36+$K$22*10^E36+$K$20)) -> 2.9136454 | K36: =IF(D36=0,"",1/(1+10^D36*$J$15/$J$14+10^E36*$J$16/$J$14+10^J36*$J$19/$J$14)) -> 0.051500004 | L36: =IF(D36=0,"",1/(1+10^I36/10^J36*$J$13/$J$19)) -> 0.0056577903 | M36: =IF(D36=0,"",1-L36) -> 0.99434221 | N36: =IF(D36=0,"",1/(1/10^E36*$J$20/$J$22+10^D36/10^E36*$J$21/$J$22+10^I36/10^E36*$J$13/$J$22+1)) -> 0.0045085563 | O36: =IF(D36=0,"",F36*K36*$J$7/$J$14) -> 5.1775065e-08 | P36: =IF(D36=0,"",O36*10^J36) -> 4.2439085e-05 | Q36: =IF(D36=0,"",F36*N36*$J$7/$J$22) -> 0.00067637361 | R36: =F36*$C$14 -> 0.00015 | S36: =$R36*L36 -> 8.4866854e-07 | T36: =R36*K36 -> 7.7250006e-06 | U36: =$R36*M36 -> 0.00014915133 | V36: =K36/M36 -> 0.051793038
B37: hexachlorophene | C37: 70-30-4 | D37: 4.9025336 | E37: 6.4965619 | F37: 1e-06 | I37: =IF(D37=0,"",LOG($K$15*10^D37+$K$16*10^E37+$K$14)) -> 3.1977472 | J37: =IF(D37=0,"",LOG($K$21*10^D37+$K$22*10^E37+$K$20)) -> 5.2086076 | K37: =IF(D37=0,"",1/(1+10^D37*$J$15/$J$14+10^E37*$J$16/$J$14+10^J37*$J$19/$J$14)) -> 0.00062244401 | L37: =IF(D37=0,"",1/(1+10^I37/10^J37*$J$13/$J$19)) -> 0.013486588 | M37: =IF(D37=0,"",1-L37) -> 0.98651341 | N37: =IF(D37=0,"",1/(1/10^E37*$J$20/$J$22+10^D37/10^E37*$J$21/$J$22+10^I37/10^E37*$J$13/$J$22+1)) -> 0.013086588 | O37: =IF(D37=0,"",F37*K37*$J$7/$J$14) -> 6.2576848e-10 | P37: =IF(D37=0,"",O37*10^J37) -> 0.0001011629 | Q37: =IF(D37=0,"",F37*N37*$J$7/$J$22) -> 0.0019632499 | R37: =F37*$C$14 -> 0.00015 | S37: =$R37*L37 -> 2.0229882e-06 | T37: =R37*K37 -> 9.3366602e-08 | U37: =$R37*M37 -> 0.00014797701 | V37: =K37/M37 -> 0.00063095342
B38: hexamethylenetetramine | C38: 100-97-0 | D38: -0.51108881 | E38: -1.2045066 | F38: 1e-06 | I38: =IF(D38=0,"",LOG($K$15*10^D38+$K$16*10^E38+$K$14)) -> -0.0015996885 | J38: =IF(D38=0,"",LOG($K$21*10^D38+$K$22*10^E38+$K$20)) -> -0.040187316 | K38: =IF(D38=0,"",1/(1+10^D38*$J$15/$J$14+10^E38*$J$16/$J$14+10^J38*$J$19/$J$14)) -> 0.9983693 | L38: =IF(D38=0,"",1/(1+10^I38/10^J38*$J$13/$J$19)) -> 0.00012198267 | M38: =IF(D38=0,"",1-L38) -> 0.99987802 | N38: =IF(D38=0,"",1/(1/10^E38*$J$20/$J$22+10^D38/10^E38*$J$21/$J$22+10^I38/10^E38*$J$13/$J$22+1)) -> 4.1778115e-07 | O38: =IF(D38=0,"",F38*K38*$J$7/$J$14) -> 1.0037016e-06 | P38: =IF(D38=0,"",O38*10^J38) -> 9.14992e-07 | Q38: =IF(D38=0,"",F38*N38*$J$7/$J$22) -> 6.2675528e-08 | R38: =F38*$C$14 -> 0.00015 | S38: =$R38*L38 -> 1.82974e-08 | T38: =R38*K38 -> 0.00014975539 | U38: =$R38*M38 -> 0.0001499817 | V38: =K38/M38 -> 0.9984911
B39: Malathion | C39: 121-75-5 | D39: 2.341416 | E39: 2.476732 | F39: 1e-06 | I39: =IF(D39=0,"",LOG($K$15*10^D39+$K$16*10^E39+$K$14)) -> 0.33491051 | J39: =IF(D39=0,"",LOG($K$21*10^D39+$K$22*10^E39+$K$20)) -> 1.4630863 | K39: =IF(D39=0,"",1/(1+10^D39*$J$15/$J$14+10^E39*$J$16/$J$14+10^J39*$J$19/$J$14)) -> 0.45925811 | L39: =IF(D39=0,"",1/(1+10^I39/10^J39*$J$13/$J$19)) -> 0.001787876 | M39: =IF(D39=0,"",1-L39) -> 0.99821212 | N39: =IF(D39=0,"",1/(1/10^E39*$J$20/$J$22+10^D39/10^E39*$J$21/$J$22+10^I39/10^E39*$J$13/$J$22+1)) -> 0.00092247174 | O39: =IF(D39=0,"",F39*K39*$J$7/$J$14) -> 4.6171101e-07 | P39: =IF(D39=0,"",O39*10^J39) -> 1.3410858e-05 | Q39: =IF(D39=0,"",F39*N39*$J$7/$J$22) -> 0.00013838921 | R39: =F39*$C$14 -> 0.00015 | S39: =$R39*L39 -> 2.681814e-07 | T39: =R39*K39 -> 6.8888717e-05 | U39: =$R39*M39 -> 0.00014973182 | V39: =K39/M39 -> 0.46008068
... B96: Perfluorobutanesulfonic_acid | C96: 375-73-5 | D96: -5.828 | E96: -8.768 | F96: 1e-06 | I96: =IF(D96=0,"",LOG($K$15*10^D96+$K$16*10^E96+$K$14)) -> -0.0022554891 | J96: =IF(D96=0,"",LOG($K$21*10^D96+$K$22*10^E96+$K$20)) -> -0.05060995 | K96: =IF(D96=0,"",1/(1+10^D96*$J$15/$J$14+10^E96*$J$16/$J$14+10^J96*$J$19/$J$14)) -> 0.99988072 | L96: =IF(D96=0,"",1/(1+10^I96/10^J96*$J$13/$J$19)) -> 0.00011927034 | M96: =IF(D96=0,"",1-L96) -> 0.99988073 | N96: =IF(D96=0,"",1/(1/10^E96*$J$20/$J$22+10^D96/10^E96*$J$21/$J$22+10^I96/10^E96*$J$13/$J$22+1)) -> 1.1431742e-14 | O96: =IF(D96=0,"",F96*K96*$J$7/$J$14) -> 1.0052211e-06 | P96: =IF(D96=0,"",O96*10^J96) -> 8.9464686e-07 | Q96: =IF(D96=0,"",F96*N96*$J$7/$J$22) -> 1.71499e-15 | R96: =F96*$C$14 -> 0.00015 | S96: =$R96*L96 -> 1.7890552e-08 | T96: =R96*K96 -> 0.00014998211 | U96: =$R96*M96 -> 0.00014998211 | V96: =K96/M96 -> 0.99999999
B97: 4_2_Fluorotelomer_sulfonic_acid | C97: 757124-72-4 | D97: ˂1 | E97: -4.1624004 | F97: 1e-06 | I97: =IF(D97=0,"",LOG($K$15*10^D97+$K$16*10^E97+$K$14)) -> #VALUE! | J97: =IF(D97=0,"",LOG($K$21*10^D97+$K$22*10^E97+$K$20)) -> #VALUE! | K97: =IF(D97=0,"",1/(1+10^D97*$J$15/$J$14+10^E97*$J$16/$J$14+10^J97*$J$19/$J$14)) -> #VALUE! | L97: =IF(D97=0,"",1/(1+10^I97/10^J97*$J$13/$J$19)) -> #VALUE! | M97: =IF(D97=0,"",1-L97) -> #VALUE! | N97: =IF(D97=0,"",1/(1/10^E97*$J$20/$J$22+10^D97/10^E97*$J$21/$J$22+10^I97/10^E97*$J$13/$J$22+1)) -> #VALUE! | O97: =IF(D97=0,"",F97*K97*$J$7/$J$14) -> #VALUE! | P97: =IF(D97=0,"",O97*10^J97) -> #VALUE! | Q97: =IF(D97=0,"",F97*N97*$J$7/$J$22) -> #VALUE! | R97: =F97*$C$14 -> 0.00015
B98: Perfluorononanoic_acid | C98: 375-95-1 | D98: 4.54 | E98: 4.25 | F98: 1e-06 | I98: =IF(D98=0,"",LOG($K$15*10^D98+$K$16*10^E98+$K$14)) -> 2.2410132 | J98: =IF(D98=0,"",LOG($K$21*10^D98+$K$22*10^E98+$K$20)) -> 3.4728224 | K98: =IF(D98=0,"",1/(1+10^D98*$J$15/$J$14+10^E98*$J$16/$J$14+10^J98*$J$19/$J$14)) -> 0.0056982955 | L98: =IF(D98=0,"",1/(1+10^I98/10^J98*$J$13/$J$19)) -> 0.002268619 | M98: =IF(D98=0,"",1-L98) -> 0.99773138 | N98: =IF(D98=0,"",1/(1/10^E98*$J$20/$J$22+10^D98/10^E98*$J$21/$J$22+10^I98/10^E98*$J$13/$J$22+1)) -> 0.00067906165 | O98: =IF(D98=0,"",F98*K98*$J$7/$J$14) -> 5.7287301e-09 | P98: =IF(D98=0,"",O98*10^J98) -> 1.7016911e-05 | Q98: =IF(D98=0,"",F98*N98*$J$7/$J$22) -> 0.00010187283 | R98: =F98*$C$14 -> 0.00015 | S98: =$R98*L98 -> 3.4029285e-07 | T98: =R98*K98 -> 8.5474433e-07 | U98: =$R98*M98 -> 0.00014965971 | V98: =K98/M98 -> 0.0057112522
B99: Perfluorohexanoic_acid | C99: 307-24-4 | D99: 2.83 | E99: 2.32 | F99: 1e-06 | I99: =IF(D99=0,"",LOG($K$15*10^D99+$K$16*10^E99+$K$14)) -> 0.63542458 | J99: =IF(D99=0,"",LOG($K$21*10^D99+$K$22*10^E99+$K$20)) -> 1.7151796 | K99: =IF(D99=0,"",1/(1+10^D99*$J$15/$J$14+10^E99*$J$16/$J$14+10^J99*$J$19/$J$14)) -> 0.22994538 | L99: =IF(D99=0,"",1/(1+10^I99/10^J99*$J$13/$J$19)) -> 0.0015995525 | M99: =IF(D99=0,"",1-L99) -> 0.99840045 | N99: =IF(D99=0,"",1/(1/10^E99*$J$20/$J$22+10^D99/10^E99*$J$21/$J$22+10^I99/10^E99*$J$13/$J$22+1)) -> 0.00032195037 | O99: =IF(D99=0,"",F99*K99*$J$7/$J$14) -> 2.3117352e-07 | P99: =IF(D99=0,"",O99*10^J99) -> 1.1998243e-05 | Q99: =IF(D99=0,"",F99*N99*$J$7/$J$22) -> 4.8298994e-05 | R99: =F99*$C$14 -> 0.00015 | S99: =$R99*L99 -> 2.3993287e-07 | T99: =R99*K99 -> 3.4491807e-05 | U99: =$R99*M99 -> 0.00014976007 | V99: =K99/M99 -> 0.23031378
B100: Perfluorobutanoic_acid | C100: 375-22-4 | D100: ˂1 | E100: 1.7 | F100: 1e-06 | I100: =IF(D100=0,"",LOG($K$15*10^D100+$K$16*10^E100+$K$14)) -> #VALUE! | J100: =IF(D100=0,"",LOG($K$21*10^D100+$K$22*10^E100+$K$20)) -> #VALUE! | K100: =IF(D100=0,"",1/(1+10^D100*$J$15/$J$14+10^E100*$J$16/$J$14+10^J100*$J$19/$J$14)) -> #VALUE! | L100: =IF(D100=0,"",1/(1+10^I100/10^J100*$J$13/$J$19)) -> #VALUE! | M100: =IF(D100=0,"",1-L100) -> #VALUE! | N100: =IF(D100=0,"",1/(1/10^E100*$J$20/$J$22+10^D100/10^E100*$J$21/$J$22+10^I100/10^E100*$J$13/$J$22+1)) -> #VALUE! | O100: =IF(D100=0,"",F100*K100*$J$7/$J$14) -> #VALUE! | P100: =IF(D100=0,"",O100*10^J100) -> #VALUE! | Q100: =IF(D100=0,"",F100*N100*$J$7/$J$22) -> #VALUE! | R100: =F100*$C$14 -> 0.00015
B101: Perfluorooctanoic_acid | C101: 335-67-1 | D101: 4.2 | E101: 3.52 | F101: 1e-06 | I101: =IF(D101=0,"",LOG($K$15*10^D101+$K$16*10^E101+$K$14)) -> 1.893917 | J101: =IF(D101=0,"",LOG($K$21*10^D101+$K$22*10^E101+$K$20)) -> 3.0482054 | K101: =IF(D101=0,"",1/(1+10^D101*$J$15/$J$14+10^E101*$J$16/$J$14+10^J101*$J$19/$J$14)) -> 0.012676584 | L101: =IF(D101=0,"",1/(1+10^I101/10^J101*$J$13/$J$19)) -> 0.0018984616 | M101: =IF(D101=0,"",1-L101) -> 0.99810154 | N101: =IF(D101=0,"",1/(1/10^E101*$J$20/$J$22+10^D101/10^E101*$J$21/$J$22+10^I101/10^E101*$J$13/$J$22+1)) -> 0.00028129789 | O101: =IF(D101=0,"",F101*K101*$J$7/$J$14) -> 1.274429e-08 | P101: =IF(D101=0,"",O101*10^J101) -> 1.4240361e-05 | Q101: =IF(D101=0,"",F101*N101*$J$7/$J$22) -> 4.220031e-05 | R101: =F101*$C$14 -> 0.00015 | S101: =$R101*L101 -> 2.8476925e-07 | T101: =R101*K101 -> 1.9014876e-06 | U101: =$R101*M101 -> 0.00014971523 | V101: =K101/M101 -> 0.012700696
...
